Workbook

Sheet Inicio
A1: =CONCATENATE(IF(HOUR(NOW())<12,"Bom dia",IF(HOUR(NOW())<18,"Boa tarde","Boa noite")),", Renan") -> Boa tarde, Renan
A2: =CONCATENATE("Hoje é ",TEXT(TODAY(),"DD/MM/"),YEAR(TODAY())," · ",TEXT(TODAY(),"DDDD")) -> Hoje é 03/08/2026 · segunda-feira
A3: Página inicial executiva — abra esta aba todo dia. Dados ligados ao Fluxo, Agenda e Fixos.
A5: Dia de referência (simular) | B5: 10 | C5: ← mude para ver o que vence em outro dia
A7: HOJE VENCE | C7: SALDO (fluxo) | E7: PRÓXIMO RECEBIMENTO
A8: =IFERROR(INDEX(Agenda!$B$5:$B$50,MATCH(1,INDEX((Agenda!$A$5:$A$50=$B$5)*(Agenda!$D$5:$D$50="N"),0),0)),"Nada pendente hoje ✓") -> Nada pendente hoje ✓ | C8: =IFERROR(INDEX(Fluxo_Diario!$E$7:$E$37,$B$5),Fluxo_Diario!D3) -> -2940.84 | E8: =IF($B$5<15,"15/07 — GFT adiantamento",IF($B$5<30,"30/07 — Olik + GFT","Próximo mês — dia 15")) -> 15/07 — GFT adiantamento
A9: =IFERROR(INDEX(Agenda!$C$5:$C$50,MATCH(1,INDEX((Agenda!$A$5:$A$50=$B$5)*(Agenda!$D$5:$D$50="N"),0),0)),0) -> 0 | E9: =IF($B$5<15,2500,IF($B$5<30,15597.21,2500)) -> 2500
A11: Faltam para o próximo recebimento | B11: =IF($B$5<15,15-$B$5,IF($B$5<30,30-$B$5,"—")) -> 5 | C11: dias
A13: DIAS PARA SAIR DAS DÍVIDAS | C13: PRÓXIMA PRIORIDADE | E13: CAIXA LIVRE
A14: =Dashboard!L2 -> 420 | C14: =Prioridades!B12 -> Cartões | E14: =Prioridades!I3 -> 100
A17: Próximos vencimentos (7 dias a partir do dia de referência)
A18: Dia | B18: Conta | C18: Valor | D18: Pago | E18: Status
A19: =IF(Agenda!A5="","",Agenda!A5) -> 3 | B19: =IF(Agenda!A5="","",Agenda!B5) -> Contabilidade | C19: =IF(Agenda!A5="","",Agenda!C5) -> 192 | D19: =IF(Agenda!A5="","",Agenda!D5) -> S | E19: =IF(Agenda!A5="","",Agenda!E5) -> Pago
A20: =IF(Agenda!A6="","",Agenda!A6) -> 5 | B20: =IF(Agenda!A6="","",Agenda!B6) -> Acordo Caixa PF (entrada antiga — já paga) | C20: =IF(Agenda!A6="","",Agenda!C6) -> 766.03 | D20: =IF(Agenda!A6="","",Agenda!D6) -> S | E20: =IF(Agenda!A6="","",Agenda!E6) -> Pago
A21: =IF(Agenda!A7="","",Agenda!A7) -> 1 | B21: =IF(Agenda!A7="","",Agenda!B7) -> Bradesco Bruna | C21: =IF(Agenda!A7="","",Agenda!C7) -> 933 | D21: =IF(Agenda!A7="","",Agenda!D7) -> S | E21: =IF(Agenda!A7="","",Agenda!E7) -> Pago
A22: =IF(Agenda!A8="","",Agenda!A8) -> 5 | B22: =IF(Agenda!A8="","",Agenda!B8) -> Caixa PJ — 1ª parcela | C22: =IF(Agenda!A8="","",Agenda!C8) -> 565.51 | D22: =IF(Agenda!A8="","",Agenda!D8) -> S | E22: =IF(Agenda!A8="","",Agenda!E8) -> Pago
A23: =IF(Agenda!A9="","",Agenda!A9) -> 5 | B23: =IF(Agenda!A9="","",Agenda!B9) -> Carrefour Bruna (mínimo) | C23: =IF(Agenda!A9="","",Agenda!C9) -> 300 | D23: =IF(Agenda!A9="","",Agenda!D9) -> S | E23: =IF(Agenda!A9="","",Agenda!E9) -> Pago
A24: =IF(Agenda!A10="","",Agenda!A10) -> 5 | B24: =IF(Agenda!A10="","",Agenda!B10) -> Carrefour Renan (mínimo) | C24: =IF(Agenda!A10="","",Agenda!C10) -> 300 | D24: =IF(Agenda!A10="","",Agenda!D10) -> S | E24: =IF(Agenda!A10="","",Agenda!E10) -> Pago
A25: =IF(Agenda!A11="","",Agenda!A11) -> 5 | B25: =IF(Agenda!A11="","",Agenda!B11) -> Cartão Mãe (total julho) | C25: =IF(Agenda!A11="","",Agenda!C11) -> 4300 | D25: =IF(Agenda!A11="","",Agenda!D11) -> S | E25: =IF(Agenda!A11="","",Agenda!E11) -> Pago
A26: =IF(Agenda!A12="","",Agenda!A12) -> 1 | B26: =IF(Agenda!A12="","",Agenda!B12) -> Inter PJ | C26: =IF(Agenda!A12="","",Agenda!C12) -> 619 | D26: =IF(Agenda!A12="","",Agenda!D12) -> S | E26: =IF(Agenda!A12="","",Agenda!E12) -> Pago
A28: Atalhos
A29: Dashboard | B29: Visão Power BI + velocímetro + dias p/ quitação
A30: Cenarios | B30: Extra, bônus, venda — decide o que quitar
A31: Agenda | B31: Calendário completo do mês
A32: Fluxo_Diario | B32: Saldo inicial → entradas → saídas → previsto
A33: Simulador | B33: Digite quanto recebeu → recomendação automática
A34: Dash_Cartoes | B34: Uso % de cada cartão

Sheet Dashboard
A1: Dashboard Executivo — Controladoria Pessoal
A2: Estilo Power BI · 10/07/2026 · Abra Inicio todo dia | K2: dias_para_quitar | L2: =B21 -> 420
A4: RECEITA | C4: DESPESAS (fluxo jul) | E4: SOBRA / DÉFICIT
A5: =Fluxo_Diario!J5 -> 18097.21 | C5: =Fluxo_Diario!J6 -> 24967.97 | E5: =Fluxo_Diario!J7 -> 5562.34
A6: ▲ recorrente mensal | C6: ▼ saídas do mês | E6: receita − despesas do fluxo
A8: DÍVIDAS TOTAIS | C8: CAIXA LIVRE | E8: CARTÕES AGO
A9: =Emprestimos!I4 -> 113725.15 | C9: =Prioridades!I3 -> 100 | E9: =Cartoes!V2 -> 16184.16
A10: sem consignado | C10: maquininha restante | E10: faturas do mês
A12: PERCENTUAL COMPROMETIDO DA RENDA
A13: =Projecao!K2 -> 0.68506802 | B13: =IF(A13<=0.5,"🟢 SAUDÁVEL (até 50%)",IF(A13<=0.7,"🟡 ATENÇÃO (50–70%)","🔴 CRÍTICO (acima de 70%)")) -> 🟡 ATENÇÃO (50–70%)
A14: Velocímetro | B14: 0–50% 🟢 | C14: 50–70% 🟡 | D14: 70%+ 🔴
A15: Posição atual | B15: =REPT("█",ROUND(MIN(A13,1)*30,0))&REPT("░",30-ROUND(MIN(A13,1)*30,0)) -> █████████████████████░░░░░░░░░
A17: DIAS PARA SAIR DAS DÍVIDAS
A18: Superávit médio mensal (editável) | B18: 8500
A19: Passivos atuais | B19: =Emprestimos!I4 -> 113725.15
A20: Meses restantes (estimativa) | B20: =IF(B18=0,0,ROUNDUP(B19/B18,0)) -> 14
A21: Dias restantes | B21: =B20*30 -> 420 | C21: vai diminuindo conforme você quita e sobe o superávit
A23: EVOLUÇÃO DA DÍVIDA (projeção)
A24: Mês | B24: Dívida total
A25: Jul/26 | B25: 117515 | C25: =REPT("█",ROUND(B25/5000,0)) -> ████████████████████████
A26: Ago/26 | B26: 112000 | C26: =REPT("█",ROUND(B26/5000,0)) -> ██████████████████████
A27: Set/26 | B27: 108500 | C27: =REPT("█",ROUND(B27/5000,0)) -> ██████████████████████
A28: Out/26 | B28: 105000 | C28: =REPT("█",ROUND(B28/5000,0)) -> █████████████████████
A29: Nov/26 | B29: 98000 | C29: =REPT("█",ROUND(B29/5000,0)) -> ████████████████████
A30: Dez/26 | B30: 90000 | C30: =REPT("█",ROUND(B30/5000,0)) -> ██████████████████
A31: Jan/27 | B31: 82000 | C31: =REPT("█",ROUND(B31/5000,0)) -> ████████████████
A32: Fev/27 | B32: 72000 | C32: =REPT("█",ROUND(B32/5000,0)) -> ██████████████
A33: Mar/27 | B33: 62000 | C33: =REPT("█",ROUND(B33/5000,0)) -> ████████████
A34: Abr/27 | B34: 52000 | C34: =REPT("█",ROUND(B34/5000,0)) -> ██████████
A35: Mai/27 | B35: 42000 | C35: =REPT("█",ROUND(B35/5000,0)) -> ████████
A36: Jun/27 | B36: 32000 | C36: =REPT("█",ROUND(B36/5000,0)) -> ██████
A39: EVOLUÇÃO DO PATRIMÔNIO LÍQUIDO
A40: Mês | B40: PL estimado
A41: Jul/26 | B41: 56808
A42: Ago/26 | B42: 52000
A43: Set/26 | B43: 54000
A44: Out/26 | B44: 55500
A45: Nov/26 | B45: 62000
A46: Dez/26 | B46: 70000
A47: Jan/27 | B47: 78000
...

Sheet Agenda
A1: Agenda Financeira — Julho/2026 (+ IRPF até Jan/27)
A2: Marque Pago = S. Status atualiza sozinho. Vermelho = atrasado/sem caixa · Amarelo = vence em breve · Verde = pago. IRPF: dia 30 até Jan/27.
A3: Dia de hoje (referência) | B3: =Inicio!B5 -> 10
A4: Dia | B4: Conta | C4: Valor | D4: Pago (S/N) | E4: Status | F4: Categoria
A5: =IFERROR(INDEX(Contas_Ago_Jan!$B$5:$B$99,MATCH(B5,Contas_Ago_Jan!$A$5:$A$99,0)),3) -> 3 | B5: Contabilidade | C5: 192 | D5: S | E5: =IF(D5="S","Pago",IF(A5<$B$3,"Atrasado",IF(A5=$B$3,"Vence hoje",IF(A5=$B$3+1,"Vence amanhã","A vencer")))) -> Pago | F5: Serviço PJ
A6: =IFERROR(INDEX(Contas_Ago_Jan!$B$5:$B$99,MATCH(B6,Contas_Ago_Jan!$A$5:$A$99,0)),5) -> 5 | B6: Acordo Caixa PF (entrada antiga — já paga) | C6: 766.03 | D6: S | E6: =IF(D6="S","Pago",IF(A6<$B$3,"Atrasado",IF(A6=$B$3,"Vence hoje",IF(A6=$B$3+1,"Vence amanhã","A vencer")))) -> Pago | F6: Extra/julho
A7: =IFERROR(INDEX(Contas_Ago_Jan!$B$5:$B$99,MATCH(B7,Contas_Ago_Jan!$A$5:$A$99,0)),5) -> 1 | B7: Bradesco Bruna | C7: 933 | D7: S | E7: =IF(D7="S","Pago",IF(A7<$B$3,"Atrasado",IF(A7=$B$3,"Vence hoje",IF(A7=$B$3+1,"Vence amanhã","A vencer")))) -> Pago | F7: Extra/julho
A8: =IFERROR(INDEX(Contas_Ago_Jan!$B$5:$B$99,MATCH(B8,Contas_Ago_Jan!$A$5:$A$99,0)),5) -> 5 | B8: Caixa PJ — 1ª parcela | C8: 565.51 | D8: S | E8: =IF(D8="S","Pago",IF(A8<$B$3,"Atrasado",IF(A8=$B$3,"Vence hoje",IF(A8=$B$3+1,"Vence amanhã","A vencer")))) -> Pago | F8: Extra/julho
A9: =IFERROR(INDEX(Contas_Ago_Jan!$B$5:$B$99,MATCH(B9,Contas_Ago_Jan!$A$5:$A$99,0)),5) -> 5 | B9: Carrefour Bruna (mínimo) | C9: 300 | D9: S | E9: =IF(D9="S","Pago",IF(A9<$B$3,"Atrasado",IF(A9=$B$3,"Vence hoje",IF(A9=$B$3+1,"Vence amanhã","A vencer")))) -> Pago | F9: Extra/julho
A10: =IFERROR(INDEX(Contas_Ago_Jan!$B$5:$B$99,MATCH(B10,Contas_Ago_Jan!$A$5:$A$99,0)),5) -> 5 | B10: Carrefour Renan (mínimo) | C10: 300 | D10: S | E10: =IF(D10="S","Pago",IF(A10<$B$3,"Atrasado",IF(A10=$B$3,"Vence hoje",IF(A10=$B$3+1,"Vence amanhã","A vencer")))) -> Pago | F10: Extra/julho
A11: =IFERROR(INDEX(Contas_Ago_Jan!$B$5:$B$99,MATCH(B11,Contas_Ago_Jan!$A$5:$A$99,0)),5) -> 5 | B11: Cartão Mãe (total julho) | C11: 4300 | D11: S | E11: =IF(D11="S","Pago",IF(A11<$B$3,"Atrasado",IF(A11=$B$3,"Vence hoje",IF(A11=$B$3+1,"Vence amanhã","A vencer")))) -> Pago | F11: Extra/julho
A12: =IFERROR(INDEX(Contas_Ago_Jan!$B$5:$B$99,MATCH(B12,Contas_Ago_Jan!$A$5:$A$99,0)),5) -> 1 | B12: Inter PJ | C12: 619 | D12: S | E12: =IF(D12="S","Pago",IF(A12<$B$3,"Atrasado",IF(A12=$B$3,"Vence hoje",IF(A12=$B$3+1,"Vence amanhã","A vencer")))) -> Pago | F12: Extra/julho
A13: =IFERROR(INDEX(Contas_Ago_Jan!$B$5:$B$99,MATCH(B13,Contas_Ago_Jan!$A$5:$A$99,0)),5) -> 5 | B13: Nubank PF — acordo julho | C13: 1353.13 | D13: S | E13: =IF(D13="S","Pago",IF(A13<$B$3,"Atrasado",IF(A13=$B$3,"Vence hoje",IF(A13=$B$3+1,"Vence amanhã","A vencer")))) -> Pago | F13: Empréstimo
A14: =IFERROR(INDEX(Contas_Ago_Jan!$B$5:$B$99,MATCH(B14,Contas_Ago_Jan!$A$5:$A$99,0)),5) -> 5 | B14: Porto Bank | C14: 1256 | D14: S | E14: =IF(D14="S","Pago",IF(A14<$B$3,"Atrasado",IF(A14=$B$3,"Vence hoje",IF(A14=$B$3+1,"Vence amanhã","A vencer")))) -> Pago | F14: Extra/julho
A15: =IFERROR(INDEX(Contas_Ago_Jan!$B$5:$B$99,MATCH(B15,Contas_Ago_Jan!$A$5:$A$99,0)),5) -> 5 | B15: Sam's Club (mínimo) | C15: 300 | D15: S | E15: =IF(D15="S","Pago",IF(A15<$B$3,"Atrasado",IF(A15=$B$3,"Vence hoje",IF(A15=$B$3+1,"Vence amanhã","A vencer")))) -> Pago | F15: Extra/julho
A16: =IFERROR(INDEX(Contas_Ago_Jan!$B$5:$B$99,MATCH(B16,Contas_Ago_Jan!$A$5:$A$99,0)),10) -> 10 | B16: Banco Pan — quitação | C16: 527.03 | D16: S | E16: =IF(D16="S","Pago",IF(A16<$B$3,"Atrasado",IF(A16=$B$3,"Vence hoje",IF(A16=$B$3+1,"Vence amanhã","A vencer")))) -> Pago | F16: Extra/julho
A17: =IFERROR(INDEX(Contas_Ago_Jan!$B$5:$B$99,MATCH(B17,Contas_Ago_Jan!$A$5:$A$99,0)),10) -> 3 | B17: Empr. Bruna (obra) | C17: 2280 | D17: S | E17: =IF(D17="S","Pago",IF(A17<$B$3,"Atrasado",IF(A17=$B$3,"Vence hoje",IF(A17=$B$3+1,"Vence amanhã","A vencer")))) -> Pago | F17: Empréstimo
A18: =IFERROR(INDEX(Contas_Ago_Jan!$B$5:$B$99,MATCH(B18,Contas_Ago_Jan!$A$5:$A$99,0)),10) -> 5 | B18: Internet/Telefone | C18: 385 | D18: S | E18: =IF(D18="S","Pago",IF(A18<$B$3,"Atrasado",IF(A18=$B$3,"Vence hoje",IF(A18=$B$3+1,"Vence amanhã","A vencer")))) -> Pago | F18: Serviço
A19: =IFERROR(INDEX(Contas_Ago_Jan!$B$5:$B$99,MATCH(B19,Contas_Ago_Jan!$A$5:$A$99,0)),10) -> 10 | B19: Itaú PF — 1 | C19: 558.73 | D19: S | E19: =IF(D19="S","Pago",IF(A19<$B$3,"Atrasado",IF(A19=$B$3,"Vence hoje",IF(A19=$B$3+1,"Vence amanhã","A vencer")))) -> Pago | F19: Empréstimo
A20: =IFERROR(INDEX(Contas_Ago_Jan!$B$5:$B$99,MATCH(B20,Contas_Ago_Jan!$A$5:$A$99,0)),10) -> 10 | B20: Itaú PF — 2 | C20: 400.57 | D20: S | E20: =IF(D20="S","Pago",IF(A20<$B$3,"Atrasado",IF(A20=$B$3,"Vence hoje",IF(A20=$B$3+1,"Vence amanhã","A vencer")))) -> Pago | F20: Empréstimo
A21: =IFERROR(INDEX(Contas_Ago_Jan!$B$5:$B$99,MATCH(B21,Contas_Ago_Jan!$A$5:$A$99,0)),10) -> 10 | B21: Itaú PF — 3 | C21: 337.94 | D21: S | E21: =IF(D21="S","Pago",IF(A21<$B$3,"Atrasado",IF(A21=$B$3,"Vence hoje",IF(A21=$B$3+1,"Vence amanhã","A vencer")))) -> Pago | F21: Empréstimo
A22: =IFERROR(INDEX(Contas_Ago_Jan!$B$5:$B$99,MATCH(B22,Contas_Ago_Jan!$A$5:$A$99,0)),13) -> 13 | B22: IPVA MOTO | C22: 276.64 | D22: S | E22: =IF(D22="S","Pago",IF(A22<$B$3,"Atrasado",IF(A22=$B$3,"Vence hoje",IF(A22=$B$3+1,"Vence amanhã","A vencer")))) -> Pago | F22: Extra/julho
A23: =IFERROR(INDEX(Contas_Ago_Jan!$B$5:$B$99,MATCH(B23,Contas_Ago_Jan!$A$5:$A$99,0)),14) -> 14 | B23: Depósito de material RM | C23: 400.2 | D23: S | E23: =IF(D23="S","Pago",IF(A23<$B$3,"Atrasado",IF(A23=$B$3,"Vence hoje",IF(A23=$B$3+1,"Vence amanhã","A vencer")))) -> Pago | F23: Extra/julho
A24: =IFERROR(INDEX(Contas_Ago_Jan!$B$5:$B$99,MATCH(B24,Contas_Ago_Jan!$A$5:$A$99,0)),15) -> 15 | B24: Caixa PF — boleto entrada acordo+IOF (pendente 15/07) | C24: 696.49 | D24: N | E24: =IF(D24="S","Pago",IF(A24<$B$3,"Atrasado",IF(A24=$B$3,"Vence hoje",IF(A24=$B$3+1,"Vence amanhã","A vencer")))) -> A vencer | F24: Extra/julho
A25: =IFERROR(INDEX(Contas_Ago_Jan!$B$5:$B$99,MATCH(B25,Contas_Ago_Jan!$A$5:$A$99,0)),15) -> 5 | B25: FIES Bruna | C25: 336 | D25: S | E25: =IF(D25="S","Pago",IF(A25<$B$3,"Atrasado",IF(A25=$B$3,"Vence hoje",IF(A25=$B$3+1,"Vence amanhã","A vencer")))) -> Pago | F25: Educação
A26: =IFERROR(INDEX(Contas_Ago_Jan!$B$5:$B$99,MATCH(B26,Contas_Ago_Jan!$A$5:$A$99,0)),16) -> 16 | B26: Depósito construção | C26: 500 | D26: S | E26: =IF(D26="S","Pago",IF(A26<$B$3,"Atrasado",IF(A26=$B$3,"Vence hoje",IF(A26=$B$3+1,"Vence amanhã","A vencer")))) -> Pago | F26: Obra
A27: =IFERROR(INDEX(Contas_Ago_Jan!$B$5:$B$99,MATCH(B27,Contas_Ago_Jan!$A$5:$A$99,0)),20) -> 15 | B27: Consórcio Porto | C27: 3200 | D27: S | E27: =IF(D27="S","Pago",IF(A27<$B$3,"Atrasado",IF(A27=$B$3,"Vence hoje",IF(A27=$B$3+1,"Vence amanhã","A vencer")))) -> Pago | F27: Financiamento
A28: =IFERROR(INDEX(Contas_Ago_Jan!$B$5:$B$99,MATCH(B28,Contas_Ago_Jan!$A$5:$A$99,0)),20) -> 20 | B28: DAS | C28: 685.53 | D28: N | E28: =IF(D28="S","Pago",IF(A28<$B$3,"Atrasado",IF(A28=$B$3,"Vence hoje",IF(A28=$B$3+1,"Vence amanhã","A vencer")))) -> A vencer | F28: Imposto PJ
A29: =IFERROR(INDEX(Contas_Ago_Jan!$B$5:$B$99,MATCH(B29,Contas_Ago_Jan!$A$5:$A$99,0)),23) -> 23 | B29: Bradesco PF (pendente) | C29: 1906.55 | D29: S | E29: =IF(D29="S","Pago",IF(A29<$B$3,"Atrasado",IF(A29=$B$3,"Vence hoje",IF(A29=$B$3+1,"Vence amanhã","A vencer")))) -> Pago | F29: Extra/julho
A30: =IFERROR(INDEX(Contas_Ago_Jan!$B$5:$B$99,MATCH(B30,Contas_Ago_Jan!$A$5:$A$99,0)),25) -> 15 | B30: Seguro carro | C30: 371.62 | D30: N | E30: =IF(D30="S","Pago",IF(A30<$B$3,"Atrasado",IF(A30=$B$3,"Vence hoje",IF(A30=$B$3+1,"Vence amanhã","A vencer")))) -> A vencer | F30: Seguro
A31: =IFERROR(INDEX(Contas_Ago_Jan!$B$5:$B$99,MATCH(B31,Contas_Ago_Jan!$A$5:$A$99,0)),30) -> 30 | B31: IRPF | C31: 388.03 | D31: N | E31: =IF(D31="S","Pago",IF(A31<$B$3,"Atrasado",IF(A31=$B$3,"Vence hoje",IF(A31=$B$3+1,"Vence amanhã","A vencer")))) -> A vencer | F31: Imposto PF
A33: IRPF — parcelas até Jan/27 (todo dia 30)
A34: Dia | B34: Conta | C34: Valor | D34: Pago (S/N) | E34: Status | F34: Categoria
A35: =IFERROR(INDEX(Contas_Ago_Jan!$B$5:$B$99,MATCH("IRPF",Contas_Ago_Jan!$A$5:$A$99,0)),30) -> 30 | B35: IRPF — Ago/26 | C35: 388.03 | D35: N | E35: =IF(D35="S","Pago","A vencer") -> A vencer | F35: Imposto PF
A36: =IFERROR(INDEX(Contas_Ago_Jan!$B$5:$B$99,MATCH("IRPF",Contas_Ago_Jan!$A$5:$A$99,0)),30) -> 30 | B36: IRPF — Set/26 | C36: 388.03 | D36: N | E36: =IF(D36="S","Pago","A vencer") -> A vencer | F36: Imposto PF
A37: =IFERROR(INDEX(Contas_Ago_Jan!$B$5:$B$99,MATCH("IRPF",Contas_Ago_Jan!$A$5:$A$99,0)),30) -> 30 | B37: IRPF — Out/26 | C37: 388.03 | D37: N | E37: =IF(D37="S","Pago","A vencer") -> A vencer | F37: Imposto PF
A38: =IFERROR(INDEX(Contas_Ago_Jan!$B$5:$B$99,MATCH("IRPF",Contas_Ago_Jan!$A$5:$A$99,0)),30) -> 30 | B38: IRPF — Nov/26 | C38: 388.03 | D38: N | E38: =IF(D38="S","Pago","A vencer") -> A vencer | F38: Imposto PF
A39: =IFERROR(INDEX(Contas_Ago_Jan!$B$5:$B$99,MATCH("IRPF",Contas_Ago_Jan!$A$5:$A$99,0)),30) -> 30 | B39: IRPF — Dez/26 | C39: 388.03 | D39: N | E39: =IF(D39="S","Pago","A vencer") -> A vencer | F39: Imposto PF
A40: =IFERROR(INDEX(Contas_Ago_Jan!$B$5:$B$99,MATCH("IRPF",Contas_Ago_Jan!$A$5:$A$99,0)),30) -> 30 | B40: IRPF — Jan/27 | C40: 388.03 | D40: N | E40: =IF(D40="S","Pago","A vencer") -> A vencer | F40: Imposto PF
A41: TOTAL PENDENTE (jul + IRPF futuros) | C41: =SUMIF(D5:D31,"N",C5:C31)+SUMIF(D35:D40,"N",C35:C40) -> 4469.85

Sheet Contas_Ago_Jan
A1: Contas a Pagar — Agosto/2026 a Janeiro/2027
A2: Consolidação de despesas fixas, parcelas e cartões. Edite o Dia somente nesta aba: Fixos, Cartoes, Agenda e o detalhamento abaixo serão atualizados automaticamente.
A4: Conta | B4: Dia | C4: Ago/26 | D4: Set/26 | E4: Out/26 | F4: Nov/26 | G4: Dez/26 | H4: Jan/27 | I4: Total | J4: Fonte | K4: Pago (S/N) | L4: Observação
A5: Bradesco Bruna | B5: 1 | C5: 419 | D5: 1100 | E5: 1100 | F5: 1100 | G5: 1100 | H5: 1100 | I5: =SUM(C5:H5) -> 5919 | J5: Cartões | K5: S | L5: Bradesco. Julho pago; fatura ago venc. 01/08
A6: Caixa PJ — parcelas | B6: 1 | C6: 567.74 | D6: 575.21 | E6: 582.73 | F6: 1038.67 | G6: 1010.18 | H6: 981.12 | I6: =SUM(C6:H6) -> 4755.65 | J6: Pendências | K6: N | L6: Parcelas mensais do cronograma da Caixa PJ, usando os valores com juros.
A7: Carrefour Bruna | B7: 1 | C7: 1956.45 | D7: 1292.75 | E7: 1292.75 | F7: 392.75 | G7: 392.75 | H7: 392.75 | I7: =SUM(C7:H7) -> 5720.2 | J7: Cartões | K7: S | L7: Carrefour. Limite total do banco
A8: Carrefour Renan | B8: 1 | C8: 1340.88 | D8: 1200.11 | E8: 520.78 | F8: 520.78 | G8: 520.78 | H8: 520.78 | I8: =SUM(C8:H8) -> 4624.11 | J8: Cartões | K8: S | L8: Carrefour. Limite total do banco
A9: Cartão Porto Bruna e Renan | B9: 1 | C9: 2612 | D9: 1158.96 | E9: 800 | F9: 800 | G9: 800 | H9: 800 | I9: =SUM(C9:H9) -> 6970.96 | J9: Cartões | K9: S | L9: Porto. Julho pago; fatura ago venc. 01/08
A10: Inter PJ | B10: 1 | C10: 619 | D10: 619 | E10: 619 | F10: 0 | G10: 0 | H10: 0 | I10: =SUM(C10:H10) -> 1857 | J10: Cartões | K10: N | L10: Inter. 3 parcelas restantes
A11: Itaú Click Bruna | B11: 1 | C11: 191.5 | D11: 215.54 | E11: 215.54 | F11: 215.54 | G11: 215.54 | H11: 215.54 | I11: =SUM(C11:H11) -> 1269.2 | J11: Cartões | K11: S | L11: Itaú. Fatura ago venc. 01/08 — ajuste o limite no app
A12: Itaú Gold Bruna | B12: 1 | C12: 1276 | D12: 1091.78 | E12: 1091.78 | F12: 135.78 | G12: 135.78 | H12: 135.78 | I12: =SUM(C12:H12) -> 3866.9 | J12: Cartões | K12: S | L12: Itaú. Fatura ago venc. 01/08 — ajuste o limite no app
A13: Itaú Internacional Bruna | B13: 1 | C13: 258 | D13: 258 | E13: 258 | F13: 258 | G13: 258 | H13: 258 | I13: =SUM(C13:H13) -> 1548 | J13: Cartões | K13: S | L13: Itaú. Fatura ago venc. 01/08 — ajuste o limite no app
A14: Sam's Club | B14: 1 | C14: 2610.51 | D14: 2103.73 | E14: 1120.4 | F14: 590.4 | G14: 590.4 | H14: 590.4 | I14: =SUM(C14:H14) -> 7605.84 | J14: Cartões | K14: S | L14: Sam's / Mastercard. Limite total do banco
A15: Contabilidade | B15: 3 | C15: 192 | D15: 192 | E15: 192 | F15: 192 | G15: 192 | H15: 192 | I15: =SUM(C15:H15) -> 1152 | J15: Fixos | K15: S | L15: Empresa · até Recorrente. Pago em 03/07
A16: Empr. Bruna (obra) | B16: 3 | C16: 2280 | D16: 2280 | E16: 2280 | F16: 2280 | G16: 2280 | H16: 2280 | I16: =SUM(C16:H16) -> 13680 | J16: Fixos | K16: S | L16: Particular · até Jan/2027. Julho pago
... A29: IRPF | B29: 30 | C29: 388.03 | D29: 388.03 | E29: 388.03 | F29: 388.03 | G29: 388.03 | H29: 388.03 | I29: =SUM(C29:H29) -> 2328.18 | J29: Fixos | K29: N | L29: Receita · até Jan/2027. Todo dia 30 até Jan/27 — ver Agenda
A30: TOTAL PENDENTE POR MÊS | C30: =SUMIF($K$5:$K$29,"N",C$5:C$29) -> 15061.97 | D30: =SUM(D$5:D$29) -> 23962.11 | E30: =SUM(E$5:E$29) -> 21674.31 | F30: =SUM(F$5:F$29) -> 18206.25 | G30: =SUM(G$5:G$29) -> 17677.76 | H30: =SUM(H$5:H$29) -> 17648.7 | I30: =SUM(C30:H30) -> 114231.1

Sheet Cenarios
A1: Cenários Financeiros — Simule e Decida
A2: Preencha os valores amarelos. A planilha monta o melhor uso do dinheiro, economia de juros, sobra mensal e quanto você antecipa a saída do vermelho.
A4: 1. O QUE ENTRA (edite as células amarelas) | D4: Parâmetros (editáveis)
A5: Caixa livre atual (já disponível) | B5: =Prioridades!I3 -> 100 | D5: Superávit médio mensal atual | E5: =Dashboard!B18 -> 8500
A6: Recebi extra / freelance | B6: 5000 | D6: Passivos atuais (s/ consignado) | E6: =Emprestimos!I4 -> 113725.15
A7: Bônus / 13º / PLR (à vista agora) | B7: 0 | C7: 13º GFT já na Projeção: Nov R$ 3.335,84 + Dez R$ 1.876,60 | D7: Meses até sair do vermelho (hoje) | E7: =IF(E5=0,0,ROUNDUP(E6/E5,0)) -> 14
A8: Venda de bem (ex.: carro) | B8: 0 | D8: Dias até sair do vermelho (hoje) | E8: =E7*30 -> 420
A9: Outro valor | B9: 0
A10: TOTAL DISPONÍVEL NO CENÁRIO | B10: =SUM(B5:B9) -> 5100
A12: 2. DÍVIDAS CANDIDATAS
A13: Dívida | B13: Custo p/ agir | C13: Cancela / reduz | D13: Economia imediata | E13: Juros % a.m. | F13: Juros R$/mês evitados | G13: Parcela liberada/mês | H13: Cabe no total?
A14: Caixa PJ — zerar atraso | B14: 9228.63 | C14: 9228.63 | D14: 0 | E14: 0.035 | F14: =C14*E14 -> 323.00205 | G14: 0 | H14: =IF($B$10>=B14,"SIM","PARCIAL") -> PARCIAL
A15: Mercado Pago — quitar | B15: 4155.54 | C15: 20988.81 | D15: =C15-B15 -> 16833.27 | E15: 0.08 | F15: =C15*E15 -> 1679.1048 | G15: 0 | H15: =IF($B$10>=B15,"SIM","NÃO") -> SIM
A16: Caixa PF — acordo 10x (PDF) | B16: 6540.19 | C16: 8695.21 | D16: =C16-B16 -> 2155.02 | E16: 0.0147 | F16: =C16*E16 -> 127.81959 | G16: 584.37 | H16: =IF($B$10>=B16,"SIM","NÃO") -> NÃO
A17: Nubank PF — amortizar | B17: =$B$10 -> 5100 | C17: =$B$10 -> 5100 | D17: 0 | E17: 0.04 | F17: =C17*E17 -> 204 | G17: 0 | H17: SIM
A18: Itaú PF (3) — só referência | B18: =Emprestimos!C7+Emprestimos!C8+Emprestimos!C9 -> 1297.24 | C18: =Emprestimos!B7+Emprestimos!B8+Emprestimos!B9 -> 22275.19 | D18: 0 | E18: 0.02 | F18: =C18*E18 -> 445.5038 | G18: =Emprestimos!C7+Emprestimos!C8+Emprestimos!C9 -> 1297.24 | H18: —
A20: 3. PLANO AUTOMÁTICO (melhor uso do total)
A21: Passo | B21: Ação | C21: Valor aplicado | D21: Sobra após passo | E21: Efeito
A22: 1 | B22: Caixa PJ — amortizar atraso | C22: =MIN($B$10,B14) -> 5100 | D22: =$B$10-C22 -> 0 | E22: =IF(C22>=B14,"Atraso ZERADO","Atraso reduzido em "&TEXT(C22,"R$ #,##0.00")) -> Atraso reduzido em R$ 5100,000
A23: 2 | B23: =IF(D22>=B15,"Mercado Pago — QUITAR","Mercado Pago — não cabe") -> Mercado Pago — não cabe | C23: =IF(D22>=B15,B15,0) -> 0 | D23: =D22-C23 -> 0 | E23: =IF(C23>0,"Economia "&TEXT(D15,"R$ #,##0.00")&" · cancela "&TEXT(C15,"R$ #,##0.00"),"—") -> —
A24: 3 | B24: =IF(D23>=B16,"Caixa PF — QUITAR","Caixa PF — não cabe") -> Caixa PF — não cabe | C24: =IF(D23>=B16,B16,0) -> 0 | D24: =D23-C24 -> 0 | E24: =IF(C24>0,"Economia "&TEXT(D16,"R$ #,##0.00"),"—") -> —
A25: 4 | B25: =IF(D24>0,"Nubank — amortizar restante","—") -> — | C25: =D24 -> 0 | D25: 0 | E25: =IF(C25>0,"Reduz saldo Nubank · juros evitados ~ "&TEXT(C25*E17,"R$ #,##0.00")&"/mês","—") -> —
A27: 4. RESPOSTAS AUTOMÁTICAS
A28: QUITE PRIMEIRO | C28: ECONOMIA IMEDIATA | E28: JUROS EVITADOS / MÊS
A29: =IF(C22>=B14,"Caixa PJ (atraso) — risco",IF(C23>0,"Mercado Pago — melhor ROI",IF(C24>0,"Caixa PF",IF(C22>0,"Caixa PJ (parcial)","Informe um valor no cenário")))) -> Caixa PJ (parcial) | C29: =IF(C23>0,D15,0)+IF(C24>0,D16,0) -> 0 | E29: =IF(C22>0,C22*E14,0)+IF(C23>0,F15,0)+IF(C24>0,F16,0)+IF(C25>0,C25*E17,0) -> 178.5
A32: SOBRA MENSAL AUMENTA | C32: ANTECIPA SAÍDA DO VERMELHO | E32: NOVO PRAZO | G32: passivos_apos | H32: =$E$6-IF(C23>0,C15,0)-IF(C24>0,C16,0)-C25-C22 -> 108625.15
A33: =E29 -> 178.5 | C33: =H36 -> 30 | E33: =CONCATENATE(H34," meses · ",H35," dias") -> 13 meses · 390 dias | G33: superavit_apos | H33: =$E$5+E29 -> 8678.5
G34: meses_apos | H34: =IF(H33<=0,0,ROUNDUP(MAX(0,H32)/H33,0)) -> 13
A35: (≈ juros/mês que deixam de sair + alívio de caixa) | C35: dias a menos | G35: dias_apos | H35: =H34*30 -> 390
G36: dias_ganhos | H36: =MAX(0,$E$8-H35) -> 30
A37: 5. ATALHOS DE CENÁRIO (copie o valor para a célula amarela)
A38: Cenário | B38: Valor sugerido | C38: Onde colar | D38: Obs
A39: Extra R$ 5.000 | B39: 5000 | C39: B6 | D39: Freelance / venda pequena
A40: Bônus R$ 20.000 | B40: 20000 | C40: B7 | D40: PLR / 13º / bônus
A41: Venda carro R$ 35.000 | B41: 35000 | C41: B8 | D41: Exemplo — ajuste o valor real
A42: Só caixa livre | B42: 0 | C42: B6–B9=0 | D42: Usa apenas Prioridades!I3
A44: VEREDITO DO CENÁRIO
A45: =CONCATENATE("Com R$ ",TEXT($B$10,"#,##0.00")," disponíveis: ",A29,". ","Economia imediata de R$ ",TEXT(C29,"#,##0.00"),". ","Você deixa de pagar ~R$ ",TEXT(E29,"#,##0.00"),"/mês em juros. ","Saída do vermelho antecipada em ",H36," dias (",H34," meses restantes).") -> Com R$ 5100,000 disponíveis: Caixa PJ (parcial). Economia imediata de R$ ,000. Você deixa de pagar ~R$ 178,5000/mês em juros. Saída do vermelho antecipada em 30 dias (13 meses restantes).
A49: Comparativo se aplicar TODO o valor em uma única dívida
A50: Opção única | B50: Economia | C50: Juros/mês evitados
...

Sheet Fluxo_Diario
A1: Caixa Diário — Visão de Controladoria
A2: Saldo Inicial → Entradas → Saídas → Saldo Final → Saldo Previsto. Linha vermelha = sem caixa. | I2: saldo_fim_mes | J2: =E37 -> 5562.34
A3: Mês/Ano | B3: Jul/2026 | C3: Saldo inicial do mês | D3: 0 | E3: ← edite com o saldo real | I3: total_entradas | J3: =C38 -> 30530.31
A4: Caixa livre (maquininha) | B4: =Prioridades!I3 -> 100 | I4: total_saidas | J4: =D38 -> 24967.97
I5: receita_recorrente | J5: 18097.21
A6: Dia | B6: Saldo Inicial | C6: Entradas | D6: Saídas | E6: Saldo Final | F6: Saldo Previsto* | G6: Eventos | H6: Alerta | I6: despesas_mes | J6: =D38 -> 24967.97
A7: 1 | B7: =$D$3 -> 0 | C7: 12433.1 | D7: 0 | E7: =B7+C7-D7 -> 12433.1 | F7: =E7+SUM(C8:C37)-SUM(D8:D37) -> 5562.34 | G7: + Maquininha (cartão Mãe) — extraordinária | H7: =IF(E7<0,"SEM CAIXA",IF(AND(D7>0,E7<D7*0.1),"APERTADO","")) | I7: sobra_mes | J7: =C38-D38 -> 5562.34
A8: 2 | B8: =E7 -> 12433.1 | C8: 0 | D8: 0 | E8: =B8+C8-D8 -> 12433.1 | F8: =E8+SUM(C9:C37)-SUM(D9:D37) -> 5562.34 | G8: — | H8: =IF(E8<0,"SEM CAIXA",IF(AND(D8>0,E8<D8*0.1),"APERTADO",""))
A9: 3 | B9: =E8 -> 12433.1 | C9: 0 | D9: 192 | E9: =B9+C9-D9 -> 12241.1 | F9: =E9+SUM(C10:C37)-SUM(D10:D37) -> 5562.34 | G9: ✓ Contabilidade | H9: =IF(E9<0,"SEM CAIXA",IF(AND(D9>0,E9<D9*0.1),"APERTADO",""))
A10: 4 | B10: =E9 -> 12241.1 | C10: 0 | D10: 0 | E10: =B10+C10-D10 -> 12241.1 | F10: =E10+SUM(C11:C37)-SUM(D11:D37) -> 5562.34 | G10: — | H10: =IF(E10<0,"SEM CAIXA",IF(AND(D10>0,E10<D10*0.1),"APERTADO",""))
A11: 5 | B11: =E10 -> 12241.1 | C11: 0 | D11: 10692.67 | E11: =B11+C11-D11 -> 1548.43 | F11: =E11+SUM(C12:C37)-SUM(D12:D37) -> 5562.34 | G11: ✓ Acordo Caixa PF (entrada antiga — já paga) | ✓ Nubank PF — acordo julho | ✓ Cartão Mãe (total julho) | ✓ Porto Bank | ✓ Bradesco Bruna | ✓ Sam's Club (mínimo) | ✓ Carrefour Bruna (mínimo) | ✓ Carrefour Renan (mínimo) | ✓ Inter PJ | ✓ Caixa PJ — 1ª parcela | H11: =IF(E11<0,"SEM CAIXA",IF(AND(D11>0,E11<D11*0.1),"APERTADO",""))
A12: 6 | B12: =E11 -> 1548.43 | C12: 0 | D12: 0 | E12: =B12+C12-D12 -> 1548.43 | F12: =E12+SUM(C13:C37)-SUM(D13:D37) -> 5562.34 | G12: — | H12: =IF(E12<0,"SEM CAIXA",IF(AND(D12>0,E12<D12*0.1),"APERTADO",""))
A13: 7 | B13: =E12 -> 1548.43 | C13: 0 | D13: 0 | E13: =B13+C13-D13 -> 1548.43 | F13: =E13+SUM(C14:C37)-SUM(D14:D37) -> 5562.34 | G13: — | H13: =IF(E13<0,"SEM CAIXA",IF(AND(D13>0,E13<D13*0.1),"APERTADO",""))
A14: 8 | B14: =E13 -> 1548.43 | C14: 0 | D14: 0 | E14: =B14+C14-D14 -> 1548.43 | F14: =E14+SUM(C15:C37)-SUM(D15:D37) -> 5562.34 | G14: — | H14: =IF(E14<0,"SEM CAIXA",IF(AND(D14>0,E14<D14*0.1),"APERTADO",""))
A15: 9 | B15: =E14 -> 1548.43 | C15: 0 | D15: 0 | E15: =B15+C15-D15 -> 1548.43 | F15: =E15+SUM(C16:C37)-SUM(D16:D37) -> 5562.34 | G15: — | H15: =IF(E15<0,"SEM CAIXA",IF(AND(D15>0,E15<D15*0.1),"APERTADO",""))
A16: 10 | B16: =E15 -> 1548.43 | C16: 0 | D16: 4489.27 | E16: =B16+C16-D16 -> -2940.84 | F16: =E16+SUM(C17:C37)-SUM(D17:D37) -> 5562.34 | G16: ✓ Empr. Bruna (obra) | ✓ Internet/Telefone | ✓ Itaú PF — 1 | ✓ Itaú PF — 2 | ✓ Itaú PF — 3 | ✓ Banco Pan — quitação | H16: =IF(E16<0,"SEM CAIXA",IF(AND(D16>0,E16<D16*0.1),"APERTADO","")) -> SEM CAIXA
A17: 11 | B17: =E16 -> -2940.84 | C17: 0 | D17: 0 | E17: =B17+C17-D17 -> -2940.84 | F17: =E17+SUM(C18:C37)-SUM(D18:D37) -> 5562.34 | G17: — | H17: =IF(E17<0,"SEM CAIXA",IF(AND(D17>0,E17<D17*0.1),"APERTADO","")) -> SEM CAIXA
A18: 12 | B18: =E17 -> -2940.84 | C18: 0 | D18: 0 | E18: =B18+C18-D18 -> -2940.84 | F18: =E18+SUM(C19:C37)-SUM(D19:D37) -> 5562.34 | G18: — | H18: =IF(E18<0,"SEM CAIXA",IF(AND(D18>0,E18<D18*0.1),"APERTADO","")) -> SEM CAIXA
A19: 13 | B19: =E18 -> -2940.84 | C19: 0 | D19: 276.64 | E19: =B19+C19-D19 -> -3217.48 | F19: =E19+SUM(C20:C37)-SUM(D20:D37) -> 5562.34 | G19: ✓ IPVA MOTO | H19: =IF(E19<0,"SEM CAIXA",IF(AND(D19>0,E19<D19*0.1),"APERTADO","")) -> SEM CAIXA
A20: 14 | B20: =E19 -> -3217.48 | C20: 0 | D20: 400.2 | E20: =B20+C20-D20 -> -3617.68 | F20: =E20+SUM(C21:C37)-SUM(D21:D37) -> 5562.34 | G20: ✓ Depósito de material RM | H20: =IF(E20<0,"SEM CAIXA",IF(AND(D20>0,E20<D20*0.1),"APERTADO","")) -> SEM CAIXA
A21: 15 | B21: =E20 -> -3617.68 | C21: 2500 | D21: 1032.49 | E21: =B21+C21-D21 -> -2150.17 | F21: =E21+SUM(C22:C37)-SUM(D22:D37) -> 5562.34 | G21: + GFT — adiantamento | ✓ FIES Bruna | ✓ Caixa PF — boleto entrada acordo+IOF (pendente 15/07) | H21: =IF(E21<0,"SEM CAIXA",IF(AND(D21>0,E21<D21*0.1),"APERTADO","")) -> SEM CAIXA
A22: 16 | B22: =E21 -> -2150.17 | C22: 0 | D22: 1500 | E22: =B22+C22-D22 -> -3650.17 | F22: =E22+SUM(C23:C37)-SUM(D23:D37) -> 5562.34 | G22: ○ Depósito construção | H22: =IF(E22<0,"SEM CAIXA",IF(AND(D22>0,E22<D22*0.1),"APERTADO","")) -> SEM CAIXA
A23: 17 | B23: =E22 -> -3650.17 | C23: 0 | D23: 0 | E23: =B23+C23-D23 -> -3650.17 | F23: =E23+SUM(C24:C37)-SUM(D24:D37) -> 5562.34 | G23: — | H23: =IF(E23<0,"SEM CAIXA",IF(AND(D23>0,E23<D23*0.1),"APERTADO","")) -> SEM CAIXA
A24: 18 | B24: =E23 -> -3650.17 | C24: 0 | D24: 0 | E24: =B24+C24-D24 -> -3650.17 | F24: =E24+SUM(C25:C37)-SUM(D25:D37) -> 5562.34 | G24: — | H24: =IF(E24<0,"SEM CAIXA",IF(AND(D24>0,E24<D24*0.1),"APERTADO","")) -> SEM CAIXA
A25: 19 | B25: =E24 -> -3650.17 | C25: 0 | D25: 0 | E25: =B25+C25-D25 -> -3650.17 | F25: =E25+SUM(C26:C37)-SUM(D26:D37) -> 5562.34 | G25: — | H25: =IF(E25<0,"SEM CAIXA",IF(AND(D25>0,E25<D25*0.1),"APERTADO","")) -> SEM CAIXA
A26: 20 | B26: =E25 -> -3650.17 | C26: 0 | D26: 3885.53 | E26: =B26+C26-D26 -> -7535.7 | F26: =E26+SUM(C27:C37)-SUM(D27:D37) -> 5562.34 | G26: ○ Consórcio Porto | ○ DAS | H26: =IF(E26<0,"SEM CAIXA",IF(AND(D26>0,E26<D26*0.1),"APERTADO","")) -> SEM CAIXA
A27: 21 | B27: =E26 -> -7535.7 | C27: 0 | D27: 0 | E27: =B27+C27-D27 -> -7535.7 | F27: =E27+SUM(C28:C37)-SUM(D28:D37) -> 5562.34 | G27: — | H27: =IF(E27<0,"SEM CAIXA",IF(AND(D27>0,E27<D27*0.1),"APERTADO","")) -> SEM CAIXA
A28: 22 | B28: =E27 -> -7535.7 | C28: 0 | D28: 0 | E28: =B28+C28-D28 -> -7535.7 | F28: =E28+SUM(C29:C37)-SUM(D29:D37) -> 5562.34 | G28: — | H28: =IF(E28<0,"SEM CAIXA",IF(AND(D28>0,E28<D28*0.1),"APERTADO","")) -> SEM CAIXA
A29: 23 | B29: =E28 -> -7535.7 | C29: 0 | D29: 1727.55 | E29: =B29+C29-D29 -> -9263.25 | F29: =E29+SUM(C30:C37)-SUM(D30:D37) -> 5562.34 | G29: ✓ Bradesco PF (pendente) | H29: =IF(E29<0,"SEM CAIXA",IF(AND(D29>0,E29<D29*0.1),"APERTADO","")) -> SEM CAIXA
A30: 24 | B30: =E29 -> -9263.25 | C30: 0 | D30: 0 | E30: =B30+C30-D30 -> -9263.25 | F30: =E30+SUM(C31:C37)-SUM(D31:D37) -> 5562.34 | G30: — | H30: =IF(E30<0,"SEM CAIXA",IF(AND(D30>0,E30<D30*0.1),"APERTADO","")) -> SEM CAIXA
A31: 25 | B31: =E30 -> -9263.25 | C31: 0 | D31: 371.62 | E31: =B31+C31-D31 -> -9634.87 | F31: =E31+SUM(C32:C37)-SUM(D32:D37) -> 5562.34 | G31: ○ Seguro carro | H31: =IF(E31<0,"SEM CAIXA",IF(AND(D31>0,E31<D31*0.1),"APERTADO","")) -> SEM CAIXA
A32: 26 | B32: =E31 -> -9634.87 | C32: 0 | D32: 0 | E32: =B32+C32-D32 -> -9634.87 | F32: =E32+SUM(C33:C37)-SUM(D33:D37) -> 5562.34 | G32: — | H32: =IF(E32<0,"SEM CAIXA",IF(AND(D32>0,E32<D32*0.1),"APERTADO","")) -> SEM CAIXA
A33: 27 | B33: =E32 -> -9634.87 | C33: 0 | D33: 0 | E33: =B33+C33-D33 -> -9634.87 | F33: =E33+SUM(C34:C37)-SUM(D34:D37) -> 5562.34 | G33: — | H33: =IF(E33<0,"SEM CAIXA",IF(AND(D33>0,E33<D33*0.1),"APERTADO","")) -> SEM CAIXA
A34: 28 | B34: =E33 -> -9634.87 | C34: 0 | D34: 0 | E34: =B34+C34-D34 -> -9634.87 | F34: =E34+SUM(C35:C37)-SUM(D35:D37) -> 5562.34 | G34: — | H34: =IF(E34<0,"SEM CAIXA",IF(AND(D34>0,E34<D34*0.1),"APERTADO","")) -> SEM CAIXA
A35: 29 | B35: =E34 -> -9634.87 | C35: 0 | D35: 0 | E35: =B35+C35-D35 -> -9634.87 | F35: =E35+SUM(C36:C37)-SUM(D36:D37) -> 5562.34 | G35: — | H35: =IF(E35<0,"SEM CAIXA",IF(AND(D35>0,E35<D35*0.1),"APERTADO","")) -> SEM CAIXA
A36: 30 | B36: =E35 -> -9634.87 | C36: 15597.21 | D36: 400 | E36: =B36+C36-D36 -> 5562.34 | F36: =E36+SUM(C37:C37)-SUM(D37:D37) -> 5562.34 | G36: + Olik (PJ) | + GFT — fechamento | ○ IRPF | H36: =IF(E36<0,"SEM CAIXA",IF(AND(D36>0,E36<D36*0.1),"APERTADO",""))
A37: 31 | B37: =E36 -> 5562.34 | C37: 0 | D37: 0 | E37: =B37+C37-D37 -> 5562.34 | F37: =E37 -> 5562.34 | G37: — | H37: =IF(E37<0,"SEM CAIXA",IF(AND(D37>0,E37<D37*0.1),"APERTADO",""))
A38: TOTAL | C38: =SUM(C7:C37) -> 30530.31 | D38: =SUM(D7:D37) -> 24967.97 | E38: =E37 -> 5562.34
A40: * Saldo Previsto = saldo final do dia + entradas restantes do mês − saídas restantes do mês

Sheet Fixos
A1: Despesas Fixas Recorrentes | K1: refs
A2: Marque Pago = S quando quitar. Os vencimentos vêm da coluna Dia da aba Contas_Ago_Jan. | K2: total_fixos | L2: =C19 -> 12355.68
K3: pendente_fixos | L3: =C20 -> 6741.52
A4: Conta | B4: Categoria | C4: Valor | D4: Dia venc. | E4: Banco/Origem | F4: Até quando | G4: Pago (S/N) | H4: Obs | K4: pago_fixos | L4: =C21 -> 5614.16
A5: Consórcio Porto | B5: Financiamento | C5: 3200 | D5: =IFERROR(INDEX(Contas_Ago_Jan!$B$5:$B$99,MATCH(A5,Contas_Ago_Jan!$A$5:$A$99,0)),20) -> 15 | E5: Porto | F5: Longo prazo | G5: N | H5: Pendente em julho
A6: Empr. Bruna (obra) | B6: Empréstimo | C6: 2280 | D6: =IFERROR(INDEX(Contas_Ago_Jan!$B$5:$B$99,MATCH(A6,Contas_Ago_Jan!$A$5:$A$99,0)),10) -> 3 | E6: Particular | F6: Jan/2027 | G6: S | H6: Julho pago
A7: Depósito construção | B7: Obra | C7: 1500 | D7: =IFERROR(INDEX(Contas_Ago_Jan!$B$5:$B$99,MATCH(A7,Contas_Ago_Jan!$A$5:$A$99,0)),16) -> 16 | E7: Particular | F7: Jul/2026 | G7: N | H7: Pagar à vista dia 16/07
A8: Internet/Telefone | B8: Serviço | C8: 385 | D8: =IFERROR(INDEX(Contas_Ago_Jan!$B$5:$B$99,MATCH(A8,Contas_Ago_Jan!$A$5:$A$99,0)),10) -> 5 | E8: Vivo | F8: Recorrente | G8: S | H8: Julho pago
A9: Seguro carro | B9: Seguro | C9: 371.62 | D9: =IFERROR(INDEX(Contas_Ago_Jan!$B$5:$B$99,MATCH(A9,Contas_Ago_Jan!$A$5:$A$99,0)),25) -> 15 | E9: Seguradora | F9: Abr/2027 | G9: N | H9: Pendente em julho
A10: FIES Bruna | B10: Educação | C10: 336 | D10: =IFERROR(INDEX(Contas_Ago_Jan!$B$5:$B$99,MATCH(A10,Contas_Ago_Jan!$A$5:$A$99,0)),15) -> 5 | E10: Caixa | F10: Dez/2026 | G10: S | H10: Julho pago
A11: Nubank PF (crédito) | B11: Empréstimo | C11: 1123.92 | D11: =IFERROR(INDEX(Contas_Ago_Jan!$B$5:$B$99,MATCH(A11,Contas_Ago_Jan!$A$5:$A$99,0)),10) -> 15 | E11: Nubank | F11: Jun/2028 | G11: S | H11: Jul/26 via acordo R$ 1.353,13
A12: Itaú PF — 1 | B12: Empréstimo | C12: 558.73 | D12: =IFERROR(INDEX(Contas_Ago_Jan!$B$5:$B$99,MATCH(A12,Contas_Ago_Jan!$A$5:$A$99,0)),10) -> 10 | E12: Itaú | F12: Jul/2029 | G12: S | H12: Julho pago
A13: Itaú PF — 2 | B13: Empréstimo | C13: 400.57 | D13: =IFERROR(INDEX(Contas_Ago_Jan!$B$5:$B$99,MATCH(A13,Contas_Ago_Jan!$A$5:$A$99,0)),10) -> 10 | E13: Itaú | F13: Jul/2029 | G13: S | H13: Julho pago
A14: Itaú PF — 3 | B14: Empréstimo | C14: 337.94 | D14: =IFERROR(INDEX(Contas_Ago_Jan!$B$5:$B$99,MATCH(A14,Contas_Ago_Jan!$A$5:$A$99,0)),10) -> 10 | E14: Itaú | F14: Jan/2028 | G14: S | H14: Julho pago
A15: DAS | B15: Imposto PJ | C15: 685.53 | D15: =IFERROR(INDEX(Contas_Ago_Jan!$B$5:$B$99,MATCH(A15,Contas_Ago_Jan!$A$5:$A$99,0)),20) -> 20 | E15: Governo | F15: Recorrente | G15: N | H15: Valor atualizado
A16: Contabilidade | B16: Serviço PJ | C16: 192 | D16: =IFERROR(INDEX(Contas_Ago_Jan!$B$5:$B$99,MATCH(A16,Contas_Ago_Jan!$A$5:$A$99,0)),3) -> 3 | E16: Empresa | F16: Recorrente | G16: S | H16: Pago em 03/07
A17: IRPF | B17: Imposto PF | C17: 400 | D17: =IFERROR(INDEX(Contas_Ago_Jan!$B$5:$B$99,MATCH(A17,Contas_Ago_Jan!$A$5:$A$99,0)),30) -> 30 | E17: Receita | F17: Jan/2027 | G17: N | H17: Todo dia 30 até Jan/27 — ver Agenda
A18: Caixa PF — acordo (parcela) | B18: Empréstimo | C18: 584.37 | D18: =IFERROR(INDEX(Contas_Ago_Jan!$B$5:$B$99,MATCH(A18,Contas_Ago_Jan!$A$5:$A$99,0)),15) -> 15 | E18: Caixa | F18: Abr/2027 | G18: N | H18: 10x R$ 584,37 (CET 1,47% a.m.) — 1ª em ago/26; jul só boleto 15/07
A19: TOTAL DO MÊS | C19: =SUM(C5:C18) -> 12355.68
A20: PENDENTE (não pagos) | C20: =SUMIF(G5:G18,"N",C5:C18) -> 6741.52
A21: JÁ PAGOS | C21: =SUMIF(G5:G18,"S",C5:C18) -> 5614.16

Sheet Emprestimos
A1: Empréstimos — Controle Individual | H1: refs
A2: Restam = ROUNDUP(Saldo/Parcela). Atualize o saldo após cada pagamento. | H2: dividas_parceladas | I2: =B10 -> 49249.19
H3: dividas_abertas | I3: =B18 -> 64475.96
A4: Com parcela mensal definida | H4: dividas_totais | I4: =I2+I3 -> 113725.15
A5: Banco | B5: Saldo | C5: Parcela/mês | D5: Restam | E5: Fim estimado | F5: Status | H5: caixa_pj_atraso | I5: =C14 -> 9264.93
A6: Nubank PF (crédito pessoal) | B6: 26974 | C6: 1123.92 | D6: =IF(C6=0,"—",ROUNDUP(B6/C6,0)) -> 24 | E6: Jun/2028 | F6: Em dia | H6: parcela_mensal_emp | I6: =C10 -> 2421.16
A7: Itaú PF — empréstimo 1 | B7: 7116.36 | C7: 558.73 | D7: =IF(C7=0,"—",ROUNDUP(B7/C7,0)) -> 13 | E7: Jul/2029 | F7: Em dia | H7: caixa_pj_proxima | I7: =H28 -> 567.74
A8: Itaú PF — empréstimo 2 | B8: 9893.74 | C8: 400.57 | D8: =IF(C8=0,"—",ROUNDUP(B8/C8,0)) -> 25 | E8: Jul/2029 | F8: Em dia
A9: Itaú PF — empréstimo 3 | B9: 5265.09 | C9: 337.94 | D9: =IF(C9=0,"—",ROUNDUP(B9/C9,0)) -> 16 | E9: Jan/2028 | F9: Em dia
A10: TOTAL | B10: =SUM(B6:B9) -> 49249.19 | C10: =SUM(C6:C9) -> 2421.16
A12: A regularizar / quitar
A13: Banco | B13: Saldo total | C13: Atrasado | D13: Valor quitação | E13: Prioridade | F13: Status | G13: Estratégia / Obs
A14: Caixa PJ | B14: 36946.96 | C14: =E40 -> 9264.93 | D14: 0 | E14: 1 | F14: Irregular | G14: Pagar 1 a 1 (cronograma abaixo) até aliviar cartões
A15: Mercado Pago | B15: 20988.81 | C15: 0 | D15: 4155.54 | E15: 2 | F15: Em aberto
A16: Caixa PF | B16: 6540.19 | C16: 0 | D16: 6540.19 | E16: 3 | F16: Acordo 10x
A17: Banco Pan | B17: 0 | C17: 0 | D17: 527.03 | E17: — | F17: Quitado
A18: TOTAL EM ABERTO | B18: =SUMIF(F14:F17,"<>Quitado",B14:B17) -> 64475.96 | C18: =SUM(C14:C17) -> 9264.93 | D18: =D15+D16 -> 10695.73
A20: Consignado CLT (informativo — já descontado em folha)
A21: Consignado 1 | B21: 23502.6
A22: Consignado 2 | B22: 36846
A23: Consignado 3 | B23: 22928.7
A24: TOTAL CONSIGNADO | B24: =SUM(B21:B23) -> 83277.3
A26: Caixa PJ — cronograma de parcelas (pagar 1 a 1)
A27: Marque Situação = Pago após cada pagamento. Atrasado (C14) e próxima parcela atualizam sozinhas. Caixa livre segue para aliviar cartões.
A28: # | B28: Nº parcela | C28: Situação | D28: Valor | E28: Valor c/ juros | G28: Próxima parcela (c/ juros) | H28: =IFERROR(INDEX(E29:E39,MATCH("Não Paga",C29:C39,0)),0) -> 567.74
A29: 1 | B29: 0 | C29: Não Paga | D29: 495.88 | E29: 567.74 | G29: Parcelas restantes | H29: =COUNTIF(C29:C39,"Não Paga") -> 11
A30: 2 | B30: 0 | C30: Não Paga | D30: 495.88 | E30: 575.21 | G30: Total a pagar (c/ juros) | H30: =E40 -> 9264.93
A31: 3 | B31: 0 | C31: Não Paga | D31: 495.88 | E31: 582.73
A32: 4 | B32: 1 | C32: Não Paga | D32: 919.58 | E32: 1038.67
A33: 5 | B33: 2 | C33: Não Paga | D33: 906.24 | E33: 1010.18
A34: 6 | B34: 3 | C34: Não Paga | D34: 893.1 | E34: 981.12
A35: 7 | B35: 4 | C35: Não Paga | D35: 880.14 | E35: 954.5
A36: 8 | B36: 5 | C36: Não Paga | D36: 865.95 | E36: 927.43
A37: 9 | B37: 6 | C37: Não Paga | D37: 853.74 | E37: 901.72
A38: 10 | B38: 7 | C38: Não Paga | D38: 840.25 | E38: 875.15
A39: 11 | B39: 8 | C39: Não Paga | D39: 827.76 | E39: 850.48
A40: TOTAL EM ABERTO | D40: =SUMIF(C29:C39,"Não Paga",D29:D39) -> 8474.4 | E40: =SUMIF(C29:C39,"Não Paga",E29:E39) -> 9264.93

Sheet Cartoes
A1: Cartões de Crédito — Limite Total × Utilizado × Disponível
A2: Limite Total = crédito concedido pelo banco (amarelo = editável). Utilizado = fatura atual + parcelas que ocupam limite (edite conforme o app). Disponível e % calculam sozinhos. | U2: cartoes_mes_ago | V2: =J19 -> 16184.16
A3: Status: | B3: 🟢 ≤30% Excelente | C3: 🟡 31–50% Atenção | D3: 🟠 51–80% Alto | E3: 🔴 >80% Crítico | U3: cartoes_total_restante | V3: =K19 -> 52863.92
U4: limite_total | V4: =C19 -> 78230.31
A5: Banco | B5: Cartão | C5: Limite Total | D5: Utilizado | E5: Disponível | F5: % Utilizado | G5: Fechamento | H5: Vencimento | I5: Fatura Atual | J5: Próxima Fatura | K5: Parcelas Restantes | L5: Status | U5: utilizado_total | V5: =D19 -> 54591.47
A6: Itaú | B6: Itaú Mãe (+ maquininha) | C6: 25000 | D6: 20608 | E6: =C6-D6 -> 4392 | F6: =IF(C6=0,0,D6/C6) -> 0.82432 | G6: 5 | H6: =IFERROR(INDEX(Contas_Ago_Jan!$B$5:$B$99,MATCH(B6,Contas_Ago_Jan!$A$5:$A$99,0)),10) -> 10 | I6: 4300 | J6: 4465 | K6: 20608 | L6: =IF(F6<=0.3,"🟢 Excelente",IF(F6<=0.5,"🟡 Atenção",IF(F6<=0.8,"🟠 Alto","🔴 Crítico"))) -> 🔴 Crítico | U6: disponivel_total | V6: =E19 -> 23638.84
A7: Sam's / Mastercard | B7: Sam's Club | C7: 6530 | D7: 7605.84 | E7: =C7-D7 -> -1075.84 | F7: =IF(C7=0,0,D7/C7) -> 1.1647534 | G7: 15 | H7: =IFERROR(INDEX(Contas_Ago_Jan!$B$5:$B$99,MATCH(B7,Contas_Ago_Jan!$A$5:$A$99,0)),22) -> 1 | I7: 300 | J7: 2610.51 | K7: 7605.84 | L7: =IF(F7<=0.3,"🟢 Excelente",IF(F7<=0.5,"🟡 Atenção",IF(F7<=0.8,"🟠 Alto","🔴 Crítico"))) -> 🔴 Crítico
A8: Carrefour | B8: Carrefour Bruna | C8: 5070 | D8: 5634.73 | E8: =C8-D8 -> -564.73 | F8: =IF(C8=0,0,D8/C8) -> 1.1113866 | G8: 10 | H8: =IFERROR(INDEX(Contas_Ago_Jan!$B$5:$B$99,MATCH(B8,Contas_Ago_Jan!$A$5:$A$99,0)),17) -> 1 | I8: 300 | J8: 1870.98 | K8: 5634.73 | L8: =IF(F8<=0.3,"🟢 Excelente",IF(F8<=0.5,"🟡 Atenção",IF(F8<=0.8,"🟠 Alto","🔴 Crítico"))) -> 🔴 Crítico
A9: Carrefour | B9: Carrefour Renan | C9: 3640 | D9: 4633.23 | E9: =C9-D9 -> -993.23 | F9: =IF(C9=0,0,D9/C9) -> 1.2728654 | G9: 10 | H9: =IFERROR(INDEX(Contas_Ago_Jan!$B$5:$B$99,MATCH(B9,Contas_Ago_Jan!$A$5:$A$99,0)),17) -> 1 | I9: 300 | J9: 1350 | K9: 4633.23 | L9: =IF(F9<=0.3,"🟢 Excelente",IF(F9<=0.5,"🟡 Atenção",IF(F9<=0.8,"🟠 Alto","🔴 Crítico"))) -> 🔴 Crítico
A10: Nubank | B10: Nubank PJ | C10: 5640.31 | D10: 6638.4 | E10: =C10-D10 -> -998.09 | F10: =IF(C10=0,0,D10/C10) -> 1.1769566 | G10: 1 | H10: =IFERROR(INDEX(Contas_Ago_Jan!$B$5:$B$99,MATCH(B10,Contas_Ago_Jan!$A$5:$A$99,0)),8) -> 5 | I10: 0 | J10: 737.6 | K10: 6638.4 | L10: =IF(F10<=0.3,"🟢 Excelente",IF(F10<=0.5,"🟡 Atenção",IF(F10<=0.8,"🟠 Alto","🔴 Crítico"))) -> 🔴 Crítico
A11: Inter | B11: Inter PJ | C11: 5000 | D11: 1857 | E11: =C11-D11 -> 3143 | F11: =IF(C11=0,0,D11/C11) -> 0.3714 | G11: 5 | H11: =IFERROR(INDEX(Contas_Ago_Jan!$B$5:$B$99,MATCH(B11,Contas_Ago_Jan!$A$5:$A$99,0)),1) -> 1 | I11: 619 | J11: 619 | K11: 1857 | L11: =IF(F11<=0.3,"🟢 Excelente",IF(F11<=0.5,"🟡 Atenção",IF(F11<=0.8,"🟠 Alto","🔴 Crítico"))) -> 🟡 Atenção
A12: Nubank | B12: Nubank PF (cartão) | C12: 1950 | D12: 2397.73 | E12: =C12-D12 -> -447.73 | F12: =IF(C12=0,0,D12/C12) -> 1.2296051 | G12: 1 | H12: =IFERROR(INDEX(Contas_Ago_Jan!$B$5:$B$99,MATCH(B12,Contas_Ago_Jan!$A$5:$A$99,0)),8) -> 5 | I12: 1042.08 | J12: 1042.08 | K12: 2397.73 | L12: =IF(F12<=0.3,"🟢 Excelente",IF(F12<=0.5,"🟡 Atenção",IF(F12<=0.8,"🟠 Alto","🔴 Crítico"))) -> 🔴 Crítico
A13: Bradesco | B13: Bradesco PF | C13: 3400 | D13: 1727.55 | E13: =C13-D13 -> 1672.45 | F13: =IF(C13=0,0,D13/C13) -> 0.50810294 | G13: 15 | H13: =IFERROR(INDEX(Contas_Ago_Jan!$B$5:$B$99,MATCH(B13,Contas_Ago_Jan!$A$5:$A$99,0)),23) -> 23 | I13: 1727.55 | J13: 0 | K13: 0 | L13: =IF(F13<=0.3,"🟢 Excelente",IF(F13<=0.5,"🟡 Atenção",IF(F13<=0.8,"🟠 Alto","🔴 Crítico"))) -> 🟠 Alto
A14: Itaú | B14: Itaú Gold Bruna | C14: 8000 | D14: 1141 | E14: =C14-D14 -> 6859 | F14: =IF(C14=0,0,D14/C14) -> 0.142625 | G14: 20 | H14: =IFERROR(INDEX(Contas_Ago_Jan!$B$5:$B$99,MATCH(B14,Contas_Ago_Jan!$A$5:$A$99,0)),1) -> 1 | I14: 1276 | J14: 1141 | K14: 1141 | L14: =IF(F14<=0.3,"🟢 Excelente",IF(F14<=0.5,"🟡 Atenção",IF(F14<=0.8,"🟠 Alto","🔴 Crítico"))) -> 🟢 Excelente
A15: Itaú | B15: Itaú Internacional Bruna | C15: 3000 | D15: 258 | E15: =C15-D15 -> 2742 | F15: =IF(C15=0,0,D15/C15) -> 0.086 | G15: 20 | H15: =IFERROR(INDEX(Contas_Ago_Jan!$B$5:$B$99,MATCH(B15,Contas_Ago_Jan!$A$5:$A$99,0)),1) -> 1 | I15: 258 | J15: 258 | K15: 258 | L15: =IF(F15<=0.3,"🟢 Excelente",IF(F15<=0.5,"🟡 Atenção",IF(F15<=0.8,"🟠 Alto","🔴 Crítico"))) -> 🟢 Excelente
A16: Itaú | B16: Itaú Click Bruna | C16: 2000 | D16: 122.37 | E16: =C16-D16 -> 1877.63 | F16: =IF(C16=0,0,D16/C16) -> 0.061185 | G16: 20 | H16: =IFERROR(INDEX(Contas_Ago_Jan!$B$5:$B$99,MATCH(B16,Contas_Ago_Jan!$A$5:$A$99,0)),1) -> 1 | I16: 191.5 | J16: 122.37 | K16: 122.37 | L16: =IF(F16<=0.3,"🟢 Excelente",IF(F16<=0.5,"🟡 Atenção",IF(F16<=0.8,"🟠 Alto","🔴 Crítico"))) -> 🟢 Excelente
A17: Porto | B17: Cartão Porto Bruna e Renan | C17: 5000 | D17: 1836.65 | E17: =C17-D17 -> 3163.35 | F17: =IF(C17=0,0,D17/C17) -> 0.36733 | G17: 20 | H17: =IFERROR(INDEX(Contas_Ago_Jan!$B$5:$B$99,MATCH(B17,Contas_Ago_Jan!$A$5:$A$99,0)),1) -> 1 | I17: 2612 | J17: 1836.65 | K17: 1836.65 | L17: =IF(F17<=0.3,"🟢 Excelente",IF(F17<=0.5,"🟡 Atenção",IF(F17<=0.8,"🟠 Alto","🔴 Crítico"))) -> 🟡 Atenção
A18: Bradesco | B18: Bradesco Bruna | C18: 4000 | D18: 130.97 | E18: =C18-D18 -> 3869.03 | F18: =IF(C18=0,0,D18/C18) -> 0.0327425 | G18: 20 | H18: =IFERROR(INDEX(Contas_Ago_Jan!$B$5:$B$99,MATCH(B18,Contas_Ago_Jan!$A$5:$A$99,0)),1) -> 1 | I18: 419 | J18: 130.97 | K18: 130.97 | L18: =IF(F18<=0.3,"🟢 Excelente",IF(F18<=0.5,"🟡 Atenção",IF(F18<=0.8,"🟠 Alto","🔴 Crítico"))) -> 🟢 Excelente
A19: TOTAL | C19: =SUM(C6:C18) -> 78230.31 | D19: =SUM(D6:D18) -> 54591.47 | E19: =SUM(E6:E18) -> 23638.84 | F19: =IF(C19=0,0,D19/C19) -> 0.69783016 | I19: =SUM(I6:I18) -> 13345.13 | J19: =SUM(J6:J18) -> 16184.16 | K19: =SUM(K6:K18) -> 52863.92
A21: Cronograma de parcelas futuras (detalhe)
A22: Cartão | B22: Ago/26 | C22: Set/26 | D22: Out/26 | E22: Nov/26 | F22: Dez/26 | G22: Jan/27 | H22: Fev/27 | I22: Mar/27 | J22: Abr/27 | K22: Mai/27 | L22: Total
A23: Itaú Mãe (+ maquininha) | B23: 4465 | C23: 3024 | D23: 2819 | E23: 1900 | F23: 1400 | G23: 1400 | H23: 1400 | I23: 1400 | J23: 1400 | K23: 1400 | L23: =SUM(B23:K23) -> 20608
A24: Sam's Club | B24: 2610.51 | C24: 2103.73 | D24: 1120.4 | E24: 590.4 | F24: 590.4 | G24: 590.4 | H24: 0 | I24: 0 | J24: 0 | K24: 0 | L24: =SUM(B24:K24) -> 7605.84
A25: Carrefour Bruna | B25: 1870.98 | C25: 1292.75 | D25: 1292.75 | E25: 392.75 | F25: 392.75 | G25: 392.75 | H25: 0 | I25: 0 | J25: 0 | K25: 0 | L25: =SUM(B25:K25) -> 5634.73
A26: Carrefour Renan | B26: 1350 | C26: 1200.11 | D26: 520.78 | E26: 520.78 | F26: 520.78 | G26: 520.78 | H26: 0 | I26: 0 | J26: 0 | K26: 0 | L26: =SUM(B26:K26) -> 4633.23
A27: Nubank PJ | B27: 737.6 | C27: 737.6 | D27: 737.6 | E27: 737.6 | F27: 737.6 | G27: 737.6 | H27: 737.6 | I27: 737.6 | J27: 737.6 | K27: 0 | L27: =SUM(B27:K27) -> 6638.4
A28: Inter PJ | B28: 619 | C28: 619 | D28: 619 | E28: 0 | F28: 0 | G28: 0 | H28: 0 | I28: 0 | J28: 0 | K28: 0 | L28: =SUM(B28:K28) -> 1857
A29: Nubank PF (cartão) | B29: 1042.08 | C29: 326.09 | D29: 257.39 | E29: 257.39 | F29: 257.39 | G29: 257.39 | H29: 0 | I29: 0 | J29: 0 | K29: 0 | L29: =SUM(B29:K29) -> 2397.73
A30: Bradesco PF | B30: 693.71 | C30: 669.79 | D30: 669.79 | E30: 122.51 | F30: 122.51 | G30: 122.51 | H30: 122.51 | I30: 101.42 | J30: 101.42 | K30: 101.42 | L30: =SUM(B30:K30) -> 2827.59
A31: Itaú Gold Bruna | B31: 1276 | C31: 0 | D31: 0 | E31: 0 | F31: 0 | G31: 0 | H31: 0 | I31: 0 | J31: 0 | K31: 0 | L31: =SUM(B31:K31) -> 1276
A32: Itaú Internacional Bruna | B32: 258 | C32: 0 | D32: 0 | E32: 0 | F32: 0 | G32: 0 | H32: 0 | I32: 0 | J32: 0 | K32: 0 | L32: =SUM(B32:K32) -> 258
A33: Itaú Click Bruna | B33: 191.5 | C33: 0 | D33: 0 | E33: 0 | F33: 0 | G33: 0 | H33: 0 | I33: 0 | J33: 0 | K33: 0 | L33: =SUM(B33:K33) -> 191.5
A34: Cartão Porto Bruna e Renan | B34: 2612 | C34: 0 | D34: 0 | E34: 0 | F34: 0 | G34: 0 | H34: 0 | I34: 0 | J34: 0 | K34: 0 | L34: =SUM(B34:K34) -> 2612
A35: Bradesco Bruna | B35: 419 | C35: 0 | D35: 0 | E35: 0 | F35: 0 | G35: 0 | H35: 0 | I35: 0 | J35: 0 | K35: 0 | L35: =SUM(B35:K35) -> 419
A36: TOTAL | B36: =SUM(B23:B35) -> 18145.38 | C36: =SUM(C23:C35) -> 9973.07 | D36: =SUM(D23:D35) -> 8036.71 | E36: =SUM(E23:E35) -> 4521.43 | F36: =SUM(F23:F35) -> 4021.43 | G36: =SUM(G23:G35) -> 4021.43 | H36: =SUM(H23:H35) -> 2260.11 | I36: =SUM(I23:I35) -> 2239.02 | ... L36: =SUM(L23:L35) -> 56959.02
A38: Dica: atualize a coluna Utilizado pelo app do banco (fatura aberta + parcelas). O Limite Total só muda quando o banco altera o crédito.

Sheet Dash_Cartoes
A1: Dashboard de Cartões — Uso do Limite Total
A2: Ligado à aba Cartoes. 🟢 ≤30% · 🟡 31–50% · 🟠 51–80% · 🔴 >80%
A4: Cartão | B4: Limite Total | C4: Utilizado | D4: Disponível | E4: Uso % | F4: Barra | G4: Status
A5: =Cartoes!B6 -> Itaú Mãe (+ maquininha) | B5: =Cartoes!C6 -> 25000 | C5: =Cartoes!D6 -> 20608 | D5: =Cartoes!E6 -> 4392 | E5: =Cartoes!F6 -> 0.82432 | F5: =REPT("█",ROUND(MIN(E5,1)*20,0))&REPT("░",20-ROUND(MIN(E5,1)*20,0)) -> ████████████████░░░░ | G5: =Cartoes!L6 -> 🔴 Crítico
A6: =Cartoes!B7 -> Sam's Club | B6: =Cartoes!C7 -> 6530 | C6: =Cartoes!D7 -> 7605.84 | D6: =Cartoes!E7 -> -1075.84 | E6: =Cartoes!F7 -> 1.1647534 | F6: =REPT("█",ROUND(MIN(E6,1)*20,0))&REPT("░",20-ROUND(MIN(E6,1)*20,0)) -> ████████████████████ | G6: =Cartoes!L7 -> 🔴 Crítico
A7: =Cartoes!B8 -> Carrefour Bruna | B7: =Cartoes!C8 -> 5070 | C7: =Cartoes!D8 -> 5634.73 | D7: =Cartoes!E8 -> -564.73 | E7: =Cartoes!F8 -> 1.1113866 | F7: =REPT("█",ROUND(MIN(E7,1)*20,0))&REPT("░",20-ROUND(MIN(E7,1)*20,0)) -> ████████████████████ | G7: =Cartoes!L8 -> 🔴 Crítico
A8: =Cartoes!B9 -> Carrefour Renan | B8: =Cartoes!C9 -> 3640 | C8: =Cartoes!D9 -> 4633.23 | D8: =Cartoes!E9 -> -993.23 | E8: =Cartoes!F9 -> 1.2728654 | F8: =REPT("█",ROUND(MIN(E8,1)*20,0))&REPT("░",20-ROUND(MIN(E8,1)*20,0)) -> ████████████████████ | G8: =Cartoes!L9 -> 🔴 Crítico
A9: =Cartoes!B10 -> Nubank PJ | B9: =Cartoes!C10 -> 5640.31 | C9: =Cartoes!D10 -> 6638.4 | D9: =Cartoes!E10 -> -998.09 | E9: =Cartoes!F10 -> 1.1769566 | F9: =REPT("█",ROUND(MIN(E9,1)*20,0))&REPT("░",20-ROUND(MIN(E9,1)*20,0)) -> ████████████████████ | G9: =Cartoes!L10 -> 🔴 Crítico
A10: =Cartoes!B11 -> Inter PJ | B10: =Cartoes!C11 -> 5000 | C10: =Cartoes!D11 -> 1857 | D10: =Cartoes!E11 -> 3143 | E10: =Cartoes!F11 -> 0.3714 | F10: =REPT("█",ROUND(MIN(E10,1)*20,0))&REPT("░",20-ROUND(MIN(E10,1)*20,0)) -> ███████░░░░░░░░░░░░░ | G10: =Cartoes!L11 -> 🟡 Atenção
A11: =Cartoes!B12 -> Nubank PF (cartão) | B11: =Cartoes!C12 -> 1950 | C11: =Cartoes!D12 -> 2397.73 | D11: =Cartoes!E12 -> -447.73 | E11: =Cartoes!F12 -> 1.2296051 | F11: =REPT("█",ROUND(MIN(E11,1)*20,0))&REPT("░",20-ROUND(MIN(E11,1)*20,0)) -> ████████████████████ | G11: =Cartoes!L12 -> 🔴 Crítico
A12: =Cartoes!B13 -> Bradesco PF | B12: =Cartoes!C13 -> 3400 | C12: =Cartoes!D13 -> 1727.55 | D12: =Cartoes!E13 -> 1672.45 | E12: =Cartoes!F13 -> 0.50810294 | F12: =REPT("█",ROUND(MIN(E12,1)*20,0))&REPT("░",20-ROUND(MIN(E12,1)*20,0)) -> ██████████░░░░░░░░░░ | G12: =Cartoes!L13 -> 🟠 Alto
A13: =Cartoes!B14 -> Itaú Gold Bruna | B13: =Cartoes!C14 -> 8000 | C13: =Cartoes!D14 -> 1141 | D13: =Cartoes!E14 -> 6859 | E13: =Cartoes!F14 -> 0.142625 | F13: =REPT("█",ROUND(MIN(E13,1)*20,0))&REPT("░",20-ROUND(MIN(E13,1)*20,0)) -> ███░░░░░░░░░░░░░░░░░ | G13: =Cartoes!L14 -> 🟢 Excelente
A14: =Cartoes!B15 -> Itaú Internacional Bruna | B14: =Cartoes!C15 -> 3000 | C14: =Cartoes!D15 -> 258 | D14: =Cartoes!E15 -> 2742 | E14: =Cartoes!F15 -> 0.086 | F14: =REPT("█",ROUND(MIN(E14,1)*20,0))&REPT("░",20-ROUND(MIN(E14,1)*20,0)) -> ██░░░░░░░░░░░░░░░░░░ | G14: =Cartoes!L15 -> 🟢 Excelente
A35: Limite total (soma) | B35: =Cartoes!V4 -> 78230.31
A36: Utilizado (soma) | B36: =Cartoes!V5 -> 54591.47
A37: Disponível (soma) | B37: =Cartoes!V6 -> 23638.84

Sheet Prioridades
A1: Plano de Ataque — Ordem de Prioridade
A2: A primeira linha com Status diferente de Feito/Em dia é a próxima prioridade do Dashboard. | H2: proxima_prioridade | I2: =B12 -> Cartões
H3: caixa_livre | I3: 100
A4: # | B4: Dívida | C4: Ação | D4: Valor | E4: Status | F4: Motivo
A5: 1 | B5: Caixa PJ | C5: Pagar 1 parcela por vez (cronograma Empréstimos) | D5: =Emprestimos!I7 -> 567.74 | E5: Em andamento | F5: 11 parcelas no portal; 1 a 1 até aliviar cartões
A6: 2 | B6: Cartões | C6: Aliviar faturas / parcelas | D6: — | E6: Em aberto | F6: Foco do caixa livre até reduzir pressão do limite
A7: ✓ | B7: Banco Pan | C7: Quitado | D7: 527.03 | E7: Feito | F7: Pago com desconto (era R$ 552,35)
A8: 3 | B8: Mercado Pago | C8: Quitar | D8: 4155.54 | E8: Em aberto | F8: Cancela R$ 20.988 — ROI 80% (após alívio dos cartões)
A9: 4 | B9: Caixa PF | C9: Acordo 10x R$ 584,37 | D9: 6540.19 | E9: Em acordo | F9: Boleto R$ 696,49 (15/07) + 10x R$ 584,37 — dívida R$ 8.695 → paga R$ 6.540
A10: 5 | B10: Nubank / Itaú PF | C10: Manter parcelas | D10: — | E10: Em dia | F10: Manter ritmo; acelerar depois
A12: Próxima prioridade | B12: =IFERROR(INDEX(B5:B10,MATCH(1,INDEX((E5:E10="Urgente")+(E5:E10="Em aberto")+(E5:E10="Pendente")+(E5:E10="Em acordo"),0),0)),"—") -> Cartões
A13: Ação sugerida | B13: =IFERROR(INDEX(C5:C10,MATCH(1,INDEX((E5:E10="Urgente")+(E5:E10="Em aberto")+(E5:E10="Pendente")+(E5:E10="Em acordo"),0),0)),"—") -> Aliviar faturas / parcelas
A14: Valor | B14: =IFERROR(INDEX(D5:D10,MATCH(1,INDEX((E5:E10="Urgente")+(E5:E10="Em aberto")+(E5:E10="Pendente")+(E5:E10="Em acordo"),0),0)),"—") -> —
A16: Uso do caixa livre (maquininha) — histórico
A17: # | B17: Destino | C17: Pagar | D17: Sobra | E17: Motivo
A18: ✓ | B18: Acordo Caixa PF (entrada antiga) | C18: 766.03 | D18: 11667.07 | E18: Já pago
A19: ✓ | B19: Nubank PF — acordo julho | C19: 1353.13 | D19: 10313.94 | E19: Já pago
A20: ✓ | B20: Cartão Mãe (total julho) | C20: 4300 | D20: 6013.94 | E20: Já pago
A21: ✓ | B21: Banco Pan — quitação | C21: 527.03 | D21: 5486.91 | E21: Já pago — desconto R$ 25,32
A22: 1 | B22: Caixa PF — boleto entrada+IOF 15/07 | C22: 696.49 | D22: 4309.55 | E22: Pagar — depois 10x R$ 584,37
A23: 2 | B23: Cartões — aliviar faturas/parcelas | C23: 4309.55 | D23: 0 | E23: Foco do caixa livre — Caixa PJ segue 1 parcela por vez
A25: Caixa PJ: 11 parcelas no portal (3x nº0 + parcelas 1–8). Pagar 1 a 1 pelo valor c/ juros. Caixa livre continua para aliviar cartões. Atualize Situação=Pago na aba Empréstimos após cada pagamento.

Sheet Ranking
A1: Ranking das Dívidas — Juros × Prioridade × Economia
A2: Juros/mês estimados (edite). Economia = saldo − custo de quitação. Prioridade considera risco + ROI.
A4: # | B4: Dívida | C4: Saldo | D4: Juros % a.m. | E4: Juros R$/mês | F4: Custo quitação | G4: Economia | H4: Prioridade | I4: Motivo
A5: 1 | B5: Caixa PJ (atraso) | C5: =Emprestimos!C14 -> 9264.93 | D5: 0.035 | E5: =IF(ISNUMBER(C5),C5*D5,0) -> 324.27255 | F5: =Emprestimos!C14 -> 9264.93 | G5: =IF(F5=0,0,MAX(0,C5-F5)) -> 0 | H5: 1 | I5: Risco de negativação
A6: 2 | B6: Mercado Pago | C6: =Emprestimos!B15 -> 20988.81 | D6: 0.08 | E6: =IF(ISNUMBER(C6),C6*D6,0) -> 1679.1048 | F6: =Emprestimos!D15 -> 4155.54 | G6: =IF(F6=0,0,MAX(0,C6-F6)) -> 16833.27 | H6: 2 | I6: ROI ~80%
A7: 3 | B7: Caixa PF | C7: =Emprestimos!B16 -> 6540.19 | D7: 0.0147 | E7: =IF(ISNUMBER(C7),C7*D7,0) -> 96.140793 | F7: =Emprestimos!D16 -> 6540.19 | G7: =IF(F7=0,0,MAX(0,C7-F7)) -> 0 | H7: 3 | I7: Acordo PDF 10x R$ 584,37
A8: 4 | B8: Nubank PF | C8: =Emprestimos!B6 -> 26974 | D8: 0.04 | E8: =IF(ISNUMBER(C8),C8*D8,0) -> 1078.96 | F8: 0 | G8: =IF(F8=0,0,MAX(0,C8-F8)) -> 0 | H8: 4 | I8: Amortizar após quitações
A9: 5 | B9: Itaú PF (3) | C9: =Emprestimos!B7+Emprestimos!B8+Emprestimos!B9 -> 22275.19 | D9: 0.02 | E9: =IF(ISNUMBER(C9),C9*D9,0) -> 445.5038 | F9: 0 | G9: =IF(F9=0,0,MAX(0,C9-F9)) -> 0 | H9: 5 | I9: Taxa menor — manter

Sheet Simulador
A1: Simulador Inteligente
A2: Digite quanto você recebeu. A planilha responde automaticamente a melhor ação.
A4: RECEBI | B4: 10000 | C4: ← digite aqui
A6: RECOMENDAÇÃO AUTOMÁTICA
A7: Quite | B7: =IF($B$4>=9228.63,"Caixa PJ (atraso completo)",IF($B$4>=6540.19,"Caixa PF (acordo 10x total) — ou Caixa PJ parcial",IF($B$4>=4155.54,"Mercado Pago (melhor ROI) — se atraso PJ estiver sob controle",IF($B$4>=696.49,"Caixa PF — pagar boleto entrada R$ 696,49 (15/07)","Caixa PJ — amortizar atraso (parcial)")))) -> Caixa PJ (atraso completo)
A8: Economia | B8: =IF(ISNUMBER(SEARCH("Mercado Pago",B7)),16833.27,IF(ISNUMBER(SEARCH("Caixa PF",B7)),2155.02,0)) -> 0
A9: Sobra | B9: =IF(ISNUMBER(SEARCH("atraso completo",B7)),$B$4-9228.63,IF(ISNUMBER(SEARCH("Mercado Pago",B7)),$B$4-4155.54,IF(ISNUMBER(SEARCH("boleto entrada",B7)),$B$4-696.49,IF(ISNUMBER(SEARCH("Caixa PF",B7)),$B$4-6540.19,0)))) -> 771.37
A11: Comparativo completo
A12: Opção | B12: Custo | C12: Cancela | D12: Economia | E12: Cabe? | F12: Sobra
A13: Caixa PJ — zerar atraso | B13: 9228.63 | C13: 9228.63 | D13: 0 | E13: =IF($B$4>=B13,"SIM","NÃO") -> SIM | F13: =IF($B$4>=B13,$B$4-B13,0) -> 771.37
A14: Mercado Pago | B14: 4155.54 | C14: 20988.81 | D14: 16833.27 | E14: =IF($B$4>=B14,"SIM","NÃO") -> SIM | F14: =IF($B$4>=B14,$B$4-B14,0) -> 5844.46
A15: Caixa PF | B15: 6540.19 | C15: 8695.21 | D15: 2155.02 | E15: =IF($B$4>=B15,"SIM","NÃO") -> SIM | F15: =IF($B$4>=B15,$B$4-B15,0) -> 3459.81
A16: MP + resto na Caixa PJ | B16: 4155.54 | C16: 20988.81 | D16: 16833.27 | E16: =IF($B$4>=B16,"SIM","NÃO") -> SIM | F16: =IF($B$4>=B16,$B$4-B16,0) -> 5844.46
A18: Regra do simulador
A19: 1) Se o valor zera o atraso da Caixa PJ → priorize isso (risco). 2) Se cabe Mercado Pago e o atraso já está controlado → melhor ROI. 3) Caso contrário → amortize Caixa PJ com tudo que tiver.

Sheet Patrimonio
A1: Controle Patrimonial
A2: Atualize ativos e passivos. Patrimônio líquido = Ativos − Passivos (sem consignado) − Consignado (opcional). | F2: ativos | G2: =B10 -> 807191.93
F3: passivos | G3: =B21 -> 166589.07
A4: Ativos | F4: pl | G4: =B27 -> 640602.86
A5: Ativo | B5: Valor | C5: Tipo | D5: Obs
A6: Consórcio Porto — carta de crédito | B6: 647391.34 | C6: Consórcio | D6: Extrato 10/07/2026 — Grupo I0254 Cota 0417-00 — Imóvel Flex | F6: Composição passivos
A7: Consórcio Porto — valor acumulado | B7: 159800.59 | C7: Consórcio | D7: Pago: FC R$ 119.032,58 + FR R$ 591,62 + Taxa Adm R$ 30.026,74 + Seguros R$ 10.149,65 (20,6510%) | F7: Dívida | G7: Saldo
A8: Reserva financeira | B8: 0 | C8: Reserva | D8: Editar quando houver | F8: =A14 -> Caixa PJ | G8: =B14 -> 36946.96
A9: Investimentos | B9: 0 | C9: Investimento | D9: Editar quando houver | F9: =A15 -> Nubank PF | G9: =B15 -> 26974
A10: TOTAL ATIVOS | B10: =SUM(B6:B9) -> 807191.93 | F10: =A16 -> Mercado Pago | G10: =B16 -> 20988.81
F11: =A17 -> Caixa PF | G11: =B17 -> 6540.19
A12: Passivos (sem consignado) | F12: =A18 -> Itaú PF (3) | G12: =B18 -> 22275.19
A13: Dívida | B13: Saldo | C13: Fonte | D13: Obs | F13: =A19 -> Cartões (parcelas futuras) | G13: =B19 -> 52863.92
A14: Caixa PJ | B14: =Emprestimos!B14 -> 36946.96 | C14: Empréstimo | D14: Irregular — pagar 1 parcela por vez até aliviar cartões
A15: Nubank PF | B15: =Emprestimos!B6 -> 26974 | C15: Empréstimo
A16: Mercado Pago | B16: =Emprestimos!B15 -> 20988.81 | C16: Empréstimo | D16: Quitação R$ 4.155,54
A17: Caixa PF | B17: =Emprestimos!B16 -> 6540.19 | C17: Empréstimo | D17: Acordo PDF — boleto R$ 696,49 (15/07) + 10x R$ 584,37 (CET 1,47%)
A18: Itaú PF (3) | B18: =Emprestimos!B7+Emprestimos!B8+Emprestimos!B9 -> 22275.19 | C18: Empréstimo
A19: Cartões (parcelas futuras) | B19: =Cartoes!V3 -> 52863.92 | C19: Cartão | D19: Saldo restante parcelado
A20: Banco Pan | B20: =Emprestimos!B17 -> 0 | C20: Empréstimo | D20: Quitado
A21: TOTAL PASSIVOS (s/ consignado) | B21: =SUM(B14:B20) -> 166589.07
A23: Consignado CLT (em folha)
A24: Total consignado | B24: =Emprestimos!B24 -> 83277.3
A26: Resumo
A27: Patrimônio líquido (s/ consignado) | B27: =B10-B21 -> 640602.86
A28: Patrimônio líquido (c/ consignado) | B28: =B10-B21-B24 -> 557325.56
A30: Meta — Casa Própria
A31: Valor alvo do imóvel | B31: 350000
A32: Carta de crédito (consórcio) | B32: =B6 -> 647391.34
A33: Entrada necessária | B33: 70000
A34: Falta para entrada | B34: =MAX(0,B33-B8-B9) -> 70000
A35: Prazo estimado | B35: Dez/2028
A37: Estratégia: quitar dívidas (2026–2028) → acumular entrada R$ 70.000 → complementar com carta do consórcio.

Sheet Projecao
A1: Projeção Financeira — Jul/2026 a Jun/2027
